<?xml version="1.0"?>
<robot name="telescope">

  <link name="base_link">
    <visual>
      <geometry>
        <cylinder length="0.6" radius="0.2"/>
      </geometry>
    </visual>
    <collision>
      <geometry>
        <cylinder length="0.6" radius="0.2"/>
      </geometry>
    </collision>

  </link>

  <link name="base_link2">
    <visual>
      <geometry>
        <cylinder length="0.1" radius="0.14"/>
      </geometry>
    </visual>
    <collision>
      <geometry>
        <cylinder length="0.1" radius="0.14"/>
      </geometry>
    </collision>
  </link>

  <joint name="dummy_base_link_joint" type="fixed">
        <parent link="base_link" />
        <child link="base_link2" />
        <origin rpy="0 0 0" xyz="0 0 0.35" />
        <axis xyz="0 0 0" />
  </joint>

  <link name="azimuth_link">
    <visual>
      <geometry>
        <cylinder length="0.03" radius="0.03"/>
      </geometry>
      <material name="Cyan">
        <color rgba="0 1.0 1.0 1.0"/>
      </material>
    </visual>

    <collision>
      <geometry>
        <cylinder length="0.03" radius="0.03"/>
      </geometry>
    </collision>

  </link>


  <joint name="az_joint" type="revolute">
    <safety_controller k_position="100.0" k_velocity="40.0" soft_lower_limit="-1.57" soft_upper_limit="1.57" />
    <limit effort="87" lower="-1.571" upper="1.571" velocity="2.3925" />
        <parent link="base_link2" />
        <child link="azimuth_link" />
        <origin rpy="0 0 0" xyz="0 0 0.05" />
        <axis xyz="0 0 1" />
  </joint>

  
  <link name="el_link">
    <visual>
      <geometry>
        <cylinder length="0.2" radius="0.01"/>
      </geometry>
      <material name="Green">
        <color rgba="0.0 1.0 0.2 1.0"/>
      </material>
    </visual>
    <collision>
      <geometry>
        <cylinder length="0.2" radius="0.01"/>
      </geometry>
    </collision>
  </link>
  


  <joint name="el_joint" type="revolute">
    <safety_controller k_position="100.0" k_velocity="40.0" soft_lower_limit="-1.57" soft_upper_limit="1.57" />
    <limit effort="87" lower="-1.571" upper="1.571" velocity="2.3925" />
        <parent link="azimuth_link" />
        <child link="el_link" />
        <origin rpy="1.57 0 0" xyz="0 0 0.05" />
        <axis xyz="0 0 1" />
  </joint>



  <link name="eef_link" />

  <joint name="eef_joint" type="revolute">
    <safety_controller k_position="100.0" k_velocity="40.0" soft_lower_limit="-1.57" soft_upper_limit="1.57" />
    <limit effort="87" lower="-1.571" upper="1.571" velocity="2.3925" />
        <parent link="el_link" />
        <child link="eef_link" />
        <origin rpy="0 0 0" xyz="0 0 0.0" />
        <axis xyz="1 0 0" />
  </joint>





  <link name="el_dummy">
    <visual>
      <geometry>
        <cylinder length="0.2" radius="0.01"/>
      </geometry>
      <material name="Green">
        <color rgba="0.0 1.0 0.2 1.0"/>
      </material>
    </visual>
    <collision>
      <geometry>
        <cylinder length="0.2" radius="0.01"/>
      </geometry>
    </collision>
  </link>


  <joint name="el_dummy_joint" type="fixed">
        <parent link="el_link" />
        <child link="el_dummy" />
        <origin rpy="1.57 0 0" xyz="0.0 0.1 0.0" />
        <axis xyz="0 0 0" />
  </joint>



</robot>
